Workbook
Name Note_sur: GARDE!$Z$4
Name tab_base: [1]CALCULS!$B$8:$K$17
Name tab_nego: [1]CALCULS!$B$36:$K$45
Name tab_recal: [1]CALCULS!$B$22:$L$31

Sheet GARDE
A1: MAITRE D’OUVRAGE
A3: ='Feuille de Donnée'!F3 -> Maitre d'ouvrage | V3: CRITERES D'ANALYSE
V4: Les offres sont classées selon une note globale sur | Z4: 10 | AA4: définie comme il suit:
A6: OPERATION | W6: Note technique | Y6: 0.4
A7: ='Feuille de Donnée'!H3 -> Déscription de l'affaire
A9: ='Feuille de Donnée'!I3 -> 1 rue de l'adresse
A15: AMO
A16: ARCHITECTE | G16: ='Feuille de Donnée'!G3 -> Maitre d'œuvre
A17: ECONOMISTE | G17: DMX Economie
A18: BUREAU D’ETUDE STRUCTURE
A19: AMO BREAM / WELL
A20: BUREAU DE CONROLE
A23: PHASE | D23: INDICE | G23: LOT
A24: ACT | D24: ='Feuille de Donnée'!M3 -> 0 | G24: ='Feuille de Donnée'!J3 -> NOMDULOT
A27: INTITULE DU DOCUMENT
A28: ANALYSE D'OFFRES
A30: N° AFFAIRE | F30: DATE | L30: REDIGE PAR | Q30: CHARGE D’AFFAIRE
A31: ='Feuille de Donnée'!L3 -> AFFAIRE | F31: ='Feuille de Donnée'!C3 -> 46077

Sheet ETANCHEITE
D1: =+'Feuille de Donnée'!E3 -> Nom du projet
D2: ='Feuille de Donnée'!H3 -> Déscription de l'affaire
D3: ='Feuille de Donnée'!B5&'Feuille de Donnée'!F3 -> Maitre d'ouvrage
D4: ='Feuille de Donnée'!B6&'Feuille de Donnée'!G3 -> Maitre d'œuvre
D5: ="INDICE : "&'Feuille de Donnée'!M3 -> INDICE : 0
D6: ="PHASE D'ETUDE : "&'Feuille de Donnée'!D3 -> PHASE D'ETUDE : ACT
D7: ="DOCUMENT EN DATE DU : "&TEXT('Feuille de Donnée'!C3,"JJ/MM/AA") -> DOCUMENT EN DATE DU : 24/02/26
D8: ='Feuille de Donnée'!K3&" : "& 'Feuille de Donnée'!J3 -> LOT 01 : NOMDULOT
D9: TABLEAU D'ANALYSE DES OFFRES :
D11: Légende analyse
D12: QUANTITE | E12: PRIX UNITAIRE | F12: Poste ajouté par MOE
D13: ="Quantité inférieuré à "&'Feuille de Donnée'!E12*100&" %" -> Quantité inférieuré à 5 % | E13: ="Prix inférieur à "&'Feuille de Donnée'!E27*100&" %" -> Prix inférieur à 35 % | F13: Poste supprimé par MOE
D14: Quantité équivalente | E14: Prix équivalent | F14: Quantité ou prix unitaire à confirmer
D15: ="Quantité supérieure a "&'Feuille de Donnée'!F12*100&" %" -> Quantité supérieure a 2 % | E15: ="Prix supérieur a "&'Feuille de Donnée'!F27*100&" %" -> Prix supérieur a 10 % | F15: Poste non renseigné par l'entreprise
G17: MOE | K17: Entreprise 1 | T17: Entreprise 2 | AC17: Entreprise 3 | AL17: Entreprise 4 | AU17: Entreprise 5 | BD17: Entreprise 6
A18: Num | B18: Désignation | G18: U | H18: Quantité | I18: PU | J18: Montant | K18: U | L18: Quantité | M18: PU | N18: Montant | O18: Ecart Qtés (en %) | P18: Ecart PU (en %) | Q18: nb remarque | R18: Remarque logiciel | S18: Questions | T18: U | U18: Quantité | V18: PU | W18: Montant | X18: Ecart Qtés (en %) | Y18: Ecart PU (en %) | Z18: nb remarque | AA18: Remarque logiciel | AB18: Questions | AC18: U | AD18: Quantité | AE18: PU | AF18: Montant | AG18: Ecart Qtés (en %) | AH18: Ecart PU (en %) | AI18: nb remarque | AJ18: Remarque logiciel | AK18: Questions | AL18: U | AM18: Quantité | AN18: PU | AO18: Montant | AP18: Ecart Qtés (en %) | AQ18: Ecart PU (en %) | AR18: nb remarque | AS18: Remarque logiciel | AT18: Questions | AU18: U | AV18: Quantité | AW18: PU | AX18: Montant | AY18: Ecart Qtés (en %) | AZ18: Ecart PU (en %) | BA18: nb remarque | BB18: Remarque logiciel | BC18: Questions | BD18: U | BE18: Quantité | BF18: PU | BG18: Montant | BH18: Ecart Qtés (en %) | BI18: Ecart PU (en %) | BJ18: nb remarque | BK18: Remarque logiciel | BL18: Questions
J19: =IF(ISBLANK(G19),"",ROUND(H19*I19,2)) | N19: =IF(ISBLANK(K19),"",ROUND(L19*M19,2)) | O19: =IF($H19=0,"",(L19/$H19-1)) | P19: =IF($I19=0,"",(M19/$I19-1)) | Q19: =IF(AND(ISBLANK(S19),R19=""),"",1+MAX(Q$18:Q18)) | R19: =IF(OR(N19="",N19=0,$J19="",$J19=0,NOT(ISNUMBER($J19)),NOT(ISNUMBER(N19))),IF(AND($G19<>"",AND(OR(ISNUMBER(N19),N19=""),AND(ISNUMBER($J19),$J19>0))),'Feuille de Donnée'!$K$13,""),IF(N19<$J$165*'Feuille de Donnée'!$I$9,"Négligeable",(IF(AND(L19>=$H19*(1-'Feuille de Donnée'!$E$12),L19<=$H19*(1+'Feuille de Donnée'!$F$12)),'Feuille de Donnée'!$F$17,IF(L19<$H19*(1-'Feuille de Donnée'!$E$12),'Feuille de Donnée'!$F$18,'Feuille de Donnée'!$F$16))&""&IF(AND(M19>=$I19*(1-'Feuille de Donnée'!$E$27),M19<=$I19*(1+'Feuille de Donnée'!$F$27)),'Feuille de Donnée'!$F$32,IF(M19<$I19*(1-'Feuille de Donnée'!$E$27),'Feuille de Donnée'!$F$33,'Feuille de Donnée'!$F$31))))) | W19: =IF(ISBLANK(T19),"",ROUND(U19*V19,2)) | X19: =IF($H19=0,"",(U19/$H19-1)) | Y19: =IF($I19=0,"",(V19/$I19-1)) | Z19: =IF(AND(ISBLANK(AB19),AA19=""),"",1+MAX(Z$18:Z18)) | AA19: =IF(OR(W19="",W19=0,$J19="",$J19=0,NOT(ISNUMBER($J19)),NOT(ISNUMBER(W19))),IF(AND($G19<>"",AND(OR(ISNUMBER(W19),W19=""),AND(ISNUMBER($J19),$J19>0))),'Feuille de Donnée'!$K$13,""),IF(W19<$J$165*'Feuille de Donnée'!$I$9,"Négligeable",(IF(AND(U19>=$H19*(1-'Feuille de Donnée'!$E$12),U19<=$H19*(1+'Feuille de Donnée'!$F$12)),'Feuille de Donnée'!$F$17,IF(U19<$H19*(1-'Feuille de Donnée'!$E$12),'Feuille de Donnée'!$F$18,'Feuille de Donnée'!$F$16))&""&IF(AND(V19>=$I19*(1-'Feuille de Donnée'!$E$27),V19<=$I19*(1+'Feuille de Donnée'!$F$27)),'Feuille de Donnée'!$F$32,IF(V19<$I19*(1-'Feuille de Donnée'!$E$27),'Feuille de Donnée'!$F$33,'Feuille de Donnée'!$F$31))))) | AF19: =IF(ISBLANK(AC19),"",ROUND(AD19*AE19,2)) | AG19: =IF($H19=0,"",(AD19/$H19-1)) | AH19: =IF($I19=0,"",(AE19/$I19-1)) | AI19: =IF(AND(ISBLANK(AK19),AJ19=""),"",1+MAX(AI$18:AI18)) | AJ19: =IF(OR(AF19="",AF19=0,$J19="",$J19=0,NOT(ISNUMBER($J19)),NOT(ISNUMBER(AF19))),IF(AND($G19<>"",AND(OR(ISNUMBER(AF19),AF19=""),AND(ISNUMBER($J19),$J19>0))),'Feuille de Donnée'!$K$13,""),IF(AF19<$J$165*'Feuille de Donnée'!$I$9,"Négligeable",(IF(AND(AD19>=$H19*(1-'Feuille de Donnée'!$E$12),AD19<=$H19*(1+'Feuille de Donnée'!$F$12)),'Feuille de Donnée'!$F$17,IF(AD19<$H19*(1-'Feuille de Donnée'!$E$12),'Feuille de Donnée'!$F$18,'Feuille de Donnée'!$F$16))&""&IF(AND(AE19>=$I19*(1-'Feuille de Donnée'!$E$27),AE19<=$I19*(1+'Feuille de Donnée'!$F$27)),'Feuille de Donnée'!$F$32,IF(AE19<$I19*(1-'Feuille de Donnée'!$E$27),'Feuille de Donnée'!$F$33,'Feuille de Donnée'!$F$31))))) | AO19: =IF(ISBLANK(AL19),"",ROUND(AM19*AN19,2)) | AP19: =IF($H19=0,"",(AM19/$H19-1)) | AQ19: =IF($I19=0,"",(AN19/$I19-1)) | AR19: =IF(AND(ISBLANK(AT19),AS19=""),"",1+MAX(AR$18:AR18)) | AS19: =IF(OR(AO19="",AO19=0,$J19="",$J19=0,NOT(ISNUMBER($J19)),NOT(ISNUMBER(AO19))),IF(AND($G19<>"",AND(OR(ISNUMBER(AO19),AO19=""),AND(ISNUMBER($J19),$J19>0))),'Feuille de Donnée'!$K$13,""),IF(AO19<$J$165*'Feuille de Donnée'!$I$9,"Négligeable",(IF(AND(AM19>=$H19*(1-'Feuille de Donnée'!$E$12),AM19<=$H19*(1+'Feuille de Donnée'!$F$12)),'Feuille de Donnée'!$F$17,IF(AM19<$H19*(1-'Feuille de Donnée'!$E$12),'Feuille de Donnée'!$F$18,'Feuille de Donnée'!$F$16))&""&IF(AND(AN19>=$I19*(1-'Feuille de Donnée'!$E$27),AN19<=$I19*(1+'Feuille de Donnée'!$F$27)),'Feuille de Donnée'!$F$32,IF(AN19<$I19*(1-'Feuille de Donnée'!$E$27),'Feuille de Donnée'!$F$33,'Feuille de Donnée'!$F$31))))) | AX19: =IF(ISBLANK(AU19),"",ROUND(AV19*AW19,2)) | AY19: =IF($H19=0,"",(AV19/$H19-1)) | AZ19: =IF($I19=0,"",(AW19/$I19-1)) | BA19: =IF(AND(ISBLANK(BC19),BB19=""),"",1+MAX(BA$18:BA18)) | BB19: =IF(OR(AX19="",AX19=0,$J19="",$J19=0,NOT(ISNUMBER($J19)),NOT(ISNUMBER(AX19))),IF(AND($G19<>"",AND(OR(ISNUMBER(AX19),AX19=""),AND(ISNUMBER($J19),$J19>0))),'Feuille de Donnée'!$K$13,""),IF(AX19<$J$165*'Feuille de Donnée'!$I$9,"Négligeable",(IF(AND(AV19>=$H19*(1-'Feuille de Donnée'!$E$12),AV19<=$H19*(1+'Feuille de Donnée'!$F$12)),'Feuille de Donnée'!$F$17,IF(AV19<$H19*(1-'Feuille de Donnée'!$E$12),'Feuille de Donnée'!$F$18,'Feuille de Donnée'!$F$16))&""&IF(AND(AW19>=$I19*(1-'Feuille de Donnée'!$E$27),AW19<=$I19*(1+'Feuille de Donnée'!$F$27)),'Feuille de Donnée'!$F$32,IF(AW19<$I19*(1-'Feuille de Donnée'!$E$27),'Feuille de Donnée'!$F$33,'Feuille de Donnée'!$F$31))))) | BG19: =IF(ISBLANK(BD19),"",ROUND(BE19*BF19,2)) | BH19: =IF($H19=0,"",(BE19/$H19-1)) | BI19: =IF($I19=0,"",(BF19/$I19-1)) | BJ19: =IF(AND(ISBLANK(BL19),BK19=""),"",1+MAX(BJ$18:BJ18)) | BK19: =IF(OR(BG19="",BG19=0,$J19="",$J19=0,NOT(ISNUMBER($J19)),NOT(ISNUMBER(BG19))),IF(AND($G19<>"",AND(OR(ISNUMBER(BG19),BG19=""),AND(ISNUMBER($J19),$J19>0))),'Feuille de Donnée'!$K$13,""),IF(BG19<$J$165*'Feuille de Donnée'!$I$9,"Négligeable",(IF(AND(BE19>=$H19*(1-'Feuille de Donnée'!$E$12),BE19<=$H19*(1+'Feuille de Donnée'!$F$12)),'Feuille de Donnée'!$F$17,IF(BE19<$H19*(1-'Feuille de Donnée'!$E$12),'Feuille de Donnée'!$F$18,'Feuille de Donnée'!$F$16))&""&IF(AND(BF19>=$I19*(1-'Feuille de Donnée'!$E$27),BF19<=$I19*(1+'Feuille de Donnée'!$F$27)),'Feuille de Donnée'!$F$32,IF(BF19<$I19*(1-'Feuille de Donnée'!$E$27),'Feuille de Donnée'!$F$33,'Feuille de Donnée'!$F$31)))))
J20: =IF(ISBLANK(G20),"",ROUND(H20*I20,2)) | N20: =IF(ISBLANK(K20),"",ROUND(L20*M20,2)) | O20: =IF($H20=0,"",(L20/$H20-1)) | P20: =IF($I20=0,"",(M20/$I20-1)) | Q20: =IF(AND(ISBLANK(S20),R20=""),"",1+MAX(Q$18:Q19)) | R20: =IF(OR(N20="",N20=0,$J20="",$J20=0,NOT(ISNUMBER($J20)),NOT(ISNUMBER(N20))),IF(AND($G20<>"",AND(OR(ISNUMBER(N20),N20=""),AND(ISNUMBER($J20),$J20>0))),'Feuille de Donnée'!$K$13,""),IF(N20<$J$165*'Feuille de Donnée'!$I$9,"Négligeable",(IF(AND(L20>=$H20*(1-'Feuille de Donnée'!$E$12),L20<=$H20*(1+'Feuille de Donnée'!$F$12)),'Feuille de Donnée'!$F$17,IF(L20<$H20*(1-'Feuille de Donnée'!$E$12),'Feuille de Donnée'!$F$18,'Feuille de Donnée'!$F$16))&""&IF(AND(M20>=$I20*(1-'Feuille de Donnée'!$E$27),M20<=$I20*(1+'Feuille de Donnée'!$F$27)),'Feuille de Donnée'!$F$32,IF(M20<$I20*(1-'Feuille de Donnée'!$E$27),'Feuille de Donnée'!$F$33,'Feuille de Donnée'!$F$31))))) | W20: =IF(ISBLANK(T20),"",ROUND(U20*V20,2)) | X20: =IF($H20=0,"",(U20/$H20-1)) | Y20: =IF($I20=0,"",(V20/$I20-1)) | Z20: =IF(AND(ISBLANK(AB20),AA20=""),"",1+MAX(Z$18:Z19)) | AA20: =IF(OR(W20="",W20=0,$J20="",$J20=0,NOT(ISNUMBER($J20)),NOT(ISNUMBER(W20))),IF(AND($G20<>"",AND(OR(ISNUMBER(W20),W20=""),AND(ISNUMBER($J20),$J20>0))),'Feuille de Donnée'!$K$13,""),IF(W20<$J$165*'Feuille de Donnée'!$I$9,"Négligeable",(IF(AND(U20>=$H20*(1-'Feuille de Donnée'!$E$12),U20<=$H20*(1+'Feuille de Donnée'!$F$12)),'Feuille de Donnée'!$F$17,IF(U20<$H20*(1-'Feuille de Donnée'!$E$12),'Feuille de Donnée'!$F$18,'Feuille de Donnée'!$F$16))&""&IF(AND(V20>=$I20*(1-'Feuille de Donnée'!$E$27),V20<=$I20*(1+'Feuille de Donnée'!$F$27)),'Feuille de Donnée'!$F$32,IF(V20<$I20*(1-'Feuille de Donnée'!$E$27),'Feuille de Donnée'!$F$33,'Feuille de Donnée'!$F$31))))) | AF20: =IF(ISBLANK(AC20),"",ROUND(AD20*AE20,2)) | AG20: =IF($H20=0,"",(AD20/$H20-1)) | AH20: =IF($I20=0,"",(AE20/$I20-1)) | AI20: =IF(AND(ISBLANK(AK20),AJ20=""),"",1+MAX(AI$18:AI19)) | AJ20: =IF(OR(AF20="",AF20=0,$J20="",$J20=0,NOT(ISNUMBER($J20)),NOT(ISNUMBER(AF20))),IF(AND($G20<>"",AND(OR(ISNUMBER(AF20),AF20=""),AND(ISNUMBER($J20),$J20>0))),'Feuille de Donnée'!$K$13,""),IF(AF20<$J$165*'Feuille de Donnée'!$I$9,"Négligeable",(IF(AND(AD20>=$H20*(1-'Feuille de Donnée'!$E$12),AD20<=$H20*(1+'Feuille de Donnée'!$F$12)),'Feuille de Donnée'!$F$17,IF(AD20<$H20*(1-'Feuille de Donnée'!$E$12),'Feuille de Donnée'!$F$18,'Feuille de Donnée'!$F$16))&""&IF(AND(AE20>=$I20*(1-'Feuille de Donnée'!$E$27),AE20<=$I20*(1+'Feuille de Donnée'!$F$27)),'Feuille de Donnée'!$F$32,IF(AE20<$I20*(1-'Feuille de Donnée'!$E$27),'Feuille de Donnée'!$F$33,'Feuille de Donnée'!$F$31))))) | AO20: =IF(ISBLANK(AL20),"",ROUND(AM20*AN20,2)) | AP20: =IF($H20=0,"",(AM20/$H20-1)) | AQ20: =IF($I20=0,"",(AN20/$I20-1)) | AR20: =IF(AND(ISBLANK(AT20),AS20=""),"",1+MAX(AR$18:AR19)) | AS20: =IF(OR(AO20="",AO20=0,$J20="",$J20=0,NOT(ISNUMBER($J20)),NOT(ISNUMBER(AO20))),IF(AND($G20<>"",AND(OR(ISNUMBER(AO20),AO20=""),AND(ISNUMBER($J20),$J20>0))),'Feuille de Donnée'!$K$13,""),IF(AO20<$J$165*'Feuille de Donnée'!$I$9,"Négligeable",(IF(AND(AM20>=$H20*(1-'Feuille de Donnée'!$E$12),AM20<=$H20*(1+'Feuille de Donnée'!$F$12)),'Feuille de Donnée'!$F$17,IF(AM20<$H20*(1-'Feuille de Donnée'!$E$12),'Feuille de Donnée'!$F$18,'Feuille de Donnée'!$F$16))&""&IF(AND(AN20>=$I20*(1-'Feuille de Donnée'!$E$27),AN20<=$I20*(1+'Feuille de Donnée'!$F$27)),'Feuille de Donnée'!$F$32,IF(AN20<$I20*(1-'Feuille de Donnée'!$E$27),'Feuille de Donnée'!$F$33,'Feuille de Donnée'!$F$31))))) | AX20: =IF(ISBLANK(AU20),"",ROUND(AV20*AW20,2)) | AY20: =IF($H20=0,"",(AV20/$H20-1)) | AZ20: =IF($I20=0,"",(AW20/$I20-1)) | BA20: =IF(AND(ISBLANK(BC20),BB20=""),"",1+MAX(BA$18:BA19)) | BB20: =IF(OR(AX20="",AX20=0,$J20="",$J20=0,NOT(ISNUMBER($J20)),NOT(ISNUMBER(AX20))),IF(AND($G20<>"",AND(OR(ISNUMBER(AX20),AX20=""),AND(ISNUMBER($J20),$J20>0))),'Feuille de Donnée'!$K$13,""),IF(AX20<$J$165*'Feuille de Donnée'!$I$9,"Négligeable",(IF(AND(AV20>=$H20*(1-'Feuille de Donnée'!$E$12),AV20<=$H20*(1+'Feuille de Donnée'!$F$12)),'Feuille de Donnée'!$F$17,IF(AV20<$H20*(1-'Feuille de Donnée'!$E$12),'Feuille de Donnée'!$F$18,'Feuille de Donnée'!$F$16))&""&IF(AND(AW20>=$I20*(1-'Feuille de Donnée'!$E$27),AW20<=$I20*(1+'Feuille de Donnée'!$F$27)),'Feuille de Donnée'!$F$32,IF(AW20<$I20*(1-'Feuille de Donnée'!$E$27),'Feuille de Donnée'!$F$33,'Feuille de Donnée'!$F$31))))) | BG20: =IF(ISBLANK(BD20),"",ROUND(BE20*BF20,2)) | BH20: =IF($H20=0,"",(BE20/$H20-1)) | BI20: =IF($I20=0,"",(BF20/$I20-1)) | BJ20: =IF(AND(ISBLANK(BL20),BK20=""),"",1+MAX(BJ$18:BJ19)) | BK20: =IF(OR(BG20="",BG20=0,$J20="",$J20=0,NOT(ISNUMBER($J20)),NOT(ISNUMBER(BG20))),IF(AND($G20<>"",AND(OR(ISNUMBER(BG20),BG20=""),AND(ISNUMBER($J20),$J20>0))),'Feuille de Donnée'!$K$13,""),IF(BG20<$J$165*'Feuille de Donnée'!$I$9,"Négligeable",(IF(AND(BE20>=$H20*(1-'Feuille de Donnée'!$E$12),BE20<=$H20*(1+'Feuille de Donnée'!$F$12)),'Feuille de Donnée'!$F$17,IF(BE20<$H20*(1-'Feuille de Donnée'!$E$12),'Feuille de Donnée'!$F$18,'Feuille de Donnée'!$F$16))&""&IF(AND(BF20>=$I20*(1-'Feuille de Donnée'!$E$27),BF20<=$I20*(1+'Feuille de Donnée'!$F$27)),'Feuille de Donnée'!$F$32,IF(BF20<$I20*(1-'Feuille de Donnée'!$E$27),'Feuille de Donnée'!$F$33,'Feuille de Donnée'!$F$31)))))
J21: =IF(ISBLANK(G21),"",ROUND(H21*I21,2)) | N21: =IF(ISBLANK(K21),"",ROUND(L21*M21,2)) | O21: =IF($H21=0,"",(L21/$H21-1)) | P21: =IF($I21=0,"",(M21/$I21-1)) | Q21: =IF(AND(ISBLANK(S21),R21=""),"",1+MAX(Q$18:Q20)) | R21: =IF(OR(N21="",N21=0,$J21="",$J21=0,NOT(ISNUMBER($J21)),NOT(ISNUMBER(N21))),IF(AND($G21<>"",AND(OR(ISNUMBER(N21),N21=""),AND(ISNUMBER($J21),$J21>0))),'Feuille de Donnée'!$K$13,""),IF(N21<$J$165*'Feuille de Donnée'!$I$9,"Négligeable",(IF(AND(L21>=$H21*(1-'Feuille de Donnée'!$E$12),L21<=$H21*(1+'Feuille de Donnée'!$F$12)),'Feuille de Donnée'!$F$17,IF(L21<$H21*(1-'Feuille de Donnée'!$E$12),'Feuille de Donnée'!$F$18,'Feuille de Donnée'!$F$16))&""&IF(AND(M21>=$I21*(1-'Feuille de Donnée'!$E$27),M21<=$I21*(1+'Feuille de Donnée'!$F$27)),'Feuille de Donnée'!$F$32,IF(M21<$I21*(1-'Feuille de Donnée'!$E$27),'Feuille de Donnée'!$F$33,'Feuille de Donnée'!$F$31))))) | W21: =IF(ISBLANK(T21),"",ROUND(U21*V21,2)) | X21: =IF($H21=0,"",(U21/$H21-1)) | Y21: =IF($I21=0,"",(V21/$I21-1)) | Z21: =IF(AND(ISBLANK(AB21),AA21=""),"",1+MAX(Z$18:Z20)) | AA21: =IF(OR(W21="",W21=0,$J21="",$J21=0,NOT(ISNUMBER($J21)),NOT(ISNUMBER(W21))),IF(AND($G21<>"",AND(OR(ISNUMBER(W21),W21=""),AND(ISNUMBER($J21),$J21>0))),'Feuille de Donnée'!$K$13,""),IF(W21<$J$165*'Feuille de Donnée'!$I$9,"Négligeable",(IF(AND(U21>=$H21*(1-'Feuille de Donnée'!$E$12),U21<=$H21*(1+'Feuille de Donnée'!$F$12)),'Feuille de Donnée'!$F$17,IF(U21<$H21*(1-'Feuille de Donnée'!$E$12),'Feuille de Donnée'!$F$18,'Feuille de Donnée'!$F$16))&""&IF(AND(V21>=$I21*(1-'Feuille de Donnée'!$E$27),V21<=$I21*(1+'Feuille de Donnée'!$F$27)),'Feuille de Donnée'!$F$32,IF(V21<$I21*(1-'Feuille de Donnée'!$E$27),'Feuille de Donnée'!$F$33,'Feuille de Donnée'!$F$31))))) | AF21: =IF(ISBLANK(AC21),"",ROUND(AD21*AE21,2)) | AG21: =IF($H21=0,"",(AD21/$H21-1)) | AH21: =IF($I21=0,"",(AE21/$I21-1)) | AI21: =IF(AND(ISBLANK(AK21),AJ21=""),"",1+MAX(AI$18:AI20)) | AJ21: =IF(OR(AF21="",AF21=0,$J21="",$J21=0,NOT(ISNUMBER($J21)),NOT(ISNUMBER(AF21))),IF(AND($G21<>"",AND(OR(ISNUMBER(AF21),AF21=""),AND(ISNUMBER($J21),$J21>0))),'Feuille de Donnée'!$K$13,""),IF(AF21<$J$165*'Feuille de Donnée'!$I$9,"Négligeable",(IF(AND(AD21>=$H21*(1-'Feuille de Donnée'!$E$12),AD21<=$H21*(1+'Feuille de Donnée'!$F$12)),'Feuille de Donnée'!$F$17,IF(AD21<$H21*(1-'Feuille de Donnée'!$E$12),'Feuille de Donnée'!$F$18,'Feuille de Donnée'!$F$16))&""&IF(AND(AE21>=$I21*(1-'Feuille de Donnée'!$E$27),AE21<=$I21*(1+'Feuille de Donnée'!$F$27)),'Feuille de Donnée'!$F$32,IF(AE21<$I21*(1-'Feuille de Donnée'!$E$27),'Feuille de Donnée'!$F$33,'Feuille de Donnée'!$F$31))))) | AO21: =IF(ISBLANK(AL21),"",ROUND(AM21*AN21,2)) | AP21: =IF($H21=0,"",(AM21/$H21-1)) | AQ21: =IF($I21=0,"",(AN21/$I21-1)) | AR21: =IF(AND(ISBLANK(AT21),AS21=""),"",1+MAX(AR$18:AR20)) | AS21: =IF(OR(AO21="",AO21=0,$J21="",$J21=0,NOT(ISNUMBER($J21)),NOT(ISNUMBER(AO21))),IF(AND($G21<>"",AND(OR(ISNUMBER(AO21),AO21=""),AND(ISNUMBER($J21),$J21>0))),'Feuille de Donnée'!$K$13,""),IF(AO21<$J$165*'Feuille de Donnée'!$I$9,"Négligeable",(IF(AND(AM21>=$H21*(1-'Feuille de Donnée'!$E$12),AM21<=$H21*(1+'Feuille de Donnée'!$F$12)),'Feuille de Donnée'!$F$17,IF(AM21<$H21*(1-'Feuille de Donnée'!$E$12),'Feuille de Donnée'!$F$18,'Feuille de Donnée'!$F$16))&""&IF(AND(AN21>=$I21*(1-'Feuille de Donnée'!$E$27),AN21<=$I21*(1+'Feuille de Donnée'!$F$27)),'Feuille de Donnée'!$F$32,IF(AN21<$I21*(1-'Feuille de Donnée'!$E$27),'Feuille de Donnée'!$F$33,'Feuille de Donnée'!$F$31))))) | AX21: =IF(ISBLANK(AU21),"",ROUND(AV21*AW21,2)) | AY21: =IF($H21=0,"",(AV21/$H21-1)) | AZ21: =IF($I21=0,"",(AW21/$I21-1)) | BA21: =IF(AND(ISBLANK(BC21),BB21=""),"",1+MAX(BA$18:BA20)) | BB21: =IF(OR(AX21="",AX21=0,$J21="",$J21=0,NOT(ISNUMBER($J21)),NOT(ISNUMBER(AX21))),IF(AND($G21<>"",AND(OR(ISNUMBER(AX21),AX21=""),AND(ISNUMBER($J21),$J21>0))),'Feuille de Donnée'!$K$13,""),IF(AX21<$J$165*'Feuille de Donnée'!$I$9,"Négligeable",(IF(AND(AV21>=$H21*(1-'Feuille de Donnée'!$E$12),AV21<=$H21*(1+'Feuille de Donnée'!$F$12)),'Feuille de Donnée'!$F$17,IF(AV21<$H21*(1-'Feuille de Donnée'!$E$12),'Feuille de Donnée'!$F$18,'Feuille de Donnée'!$F$16))&""&IF(AND(AW21>=$I21*(1-'Feuille de Donnée'!$E$27),AW21<=$I21*(1+'Feuille de Donnée'!$F$27)),'Feuille de Donnée'!$F$32,IF(AW21<$I21*(1-'Feuille de Donnée'!$E$27),'Feuille de Donnée'!$F$33,'Feuille de Donnée'!$F$31))))) | BG21: =IF(ISBLANK(BD21),"",ROUND(BE21*BF21,2)) | BH21: =IF($H21=0,"",(BE21/$H21-1)) | BI21: =IF($I21=0,"",(BF21/$I21-1)) | BJ21: =IF(AND(ISBLANK(BL21),BK21=""),"",1+MAX(BJ$18:BJ20)) | BK21: =IF(OR(BG21="",BG21=0,$J21="",$J21=0,NOT(ISNUMBER($J21)),NOT(ISNUMBER(BG21))),IF(AND($G21<>"",AND(OR(ISNUMBER(BG21),BG21=""),AND(ISNUMBER($J21),$J21>0))),'Feuille de Donnée'!$K$13,""),IF(BG21<$J$165*'Feuille de Donnée'!$I$9,"Négligeable",(IF(AND(BE21>=$H21*(1-'Feuille de Donnée'!$E$12),BE21<=$H21*(1+'Feuille de Donnée'!$F$12)),'Feuille de Donnée'!$F$17,IF(BE21<$H21*(1-'Feuille de Donnée'!$E$12),'Feuille de Donnée'!$F$18,'Feuille de Donnée'!$F$16))&""&IF(AND(BF21>=$I21*(1-'Feuille de Donnée'!$E$27),BF21<=$I21*(1+'Feuille de Donnée'!$F$27)),'Feuille de Donnée'!$F$32,IF(BF21<$I21*(1-'Feuille de Donnée'!$E$27),'Feuille de Donnée'!$F$33,'Feuille de Donnée'!$F$31)))))
J22: =IF(ISBLANK(G22),"",ROUND(H22*I22,2)) | N22: =IF(ISBLANK(K22),"",ROUND(L22*M22,2)) | O22: =IF($H22=0,"",(L22/$H22-1)) | P22: =IF($I22=0,"",(M22/$I22-1)) | Q22: =IF(AND(ISBLANK(S22),R22=""),"",1+MAX(Q$18:Q21)) | R22: =IF(OR(N22="",N22=0,$J22="",$J22=0,NOT(ISNUMBER($J22)),NOT(ISNUMBER(N22))),IF(AND($G22<>"",AND(OR(ISNUMBER(N22),N22=""),AND(ISNUMBER($J22),$J22>0))),'Feuille de Donnée'!$K$13,""),IF(N22<$J$165*'Feuille de Donnée'!$I$9,"Négligeable",(IF(AND(L22>=$H22*(1-'Feuille de Donnée'!$E$12),L22<=$H22*(1+'Feuille de Donnée'!$F$12)),'Feuille de Donnée'!$F$17,IF(L22<$H22*(1-'Feuille de Donnée'!$E$12),'Feuille de Donnée'!$F$18,'Feuille de Donnée'!$F$16))&""&IF(AND(M22>=$I22*(1-'Feuille de Donnée'!$E$27),M22<=$I22*(1+'Feuille de Donnée'!$F$27)),'Feuille de Donnée'!$F$32,IF(M22<$I22*(1-'Feuille de Donnée'!$E$27),'Feuille de Donnée'!$F$33,'Feuille de Donnée'!$F$31))))) | W22: =IF(ISBLANK(T22),"",ROUND(U22*V22,2)) | X22: =IF($H22=0,"",(U22/$H22-1)) | Y22: =IF($I22=0,"",(V22/$I22-1)) | Z22: =IF(AND(ISBLANK(AB22),AA22=""),"",1+MAX(Z$18:Z21)) | AA22: =IF(OR(W22="",W22=0,$J22="",$J22=0,NOT(ISNUMBER($J22)),NOT(ISNUMBER(W22))),IF(AND($G22<>"",AND(OR(ISNUMBER(W22),W22=""),AND(ISNUMBER($J22),$J22>0))),'Feuille de Donnée'!$K$13,""),IF(W22<$J$165*'Feuille de Donnée'!$I$9,"Négligeable",(IF(AND(U22>=$H22*(1-'Feuille de Donnée'!$E$12),U22<=$H22*(1+'Feuille de Donnée'!$F$12)),'Feuille de Donnée'!$F$17,IF(U22<$H22*(1-'Feuille de Donnée'!$E$12),'Feuille de Donnée'!$F$18,'Feuille de Donnée'!$F$16))&""&IF(AND(V22>=$I22*(1-'Feuille de Donnée'!$E$27),V22<=$I22*(1+'Feuille de Donnée'!$F$27)),'Feuille de Donnée'!$F$32,IF(V22<$I22*(1-'Feuille de Donnée'!$E$27),'Feuille de Donnée'!$F$33,'Feuille de Donnée'!$F$31))))) | AF22: =IF(ISBLANK(AC22),"",ROUND(AD22*AE22,2)) | AG22: =IF($H22=0,"",(AD22/$H22-1)) | AH22: =IF($I22=0,"",(AE22/$I22-1)) | AI22: =IF(AND(ISBLANK(AK22),AJ22=""),"",1+MAX(AI$18:AI21)) | AJ22: =IF(OR(AF22="",AF22=0,$J22="",$J22=0,NOT(ISNUMBER($J22)),NOT(ISNUMBER(AF22))),IF(AND($G22<>"",AND(OR(ISNUMBER(AF22),AF22=""),AND(ISNUMBER($J22),$J22>0))),'Feuille de Donnée'!$K$13,""),IF(AF22<$J$165*'Feuille de Donnée'!$I$9,"Négligeable",(IF(AND(AD22>=$H22*(1-'Feuille de Donnée'!$E$12),AD22<=$H22*(1+'Feuille de Donnée'!$F$12)),'Feuille de Donnée'!$F$17,IF(AD22<$H22*(1-'Feuille de Donnée'!$E$12),'Feuille de Donnée'!$F$18,'Feuille de Donnée'!$F$16))&""&IF(AND(AE22>=$I22*(1-'Feuille de Donnée'!$E$27),AE22<=$I22*(1+'Feuille de Donnée'!$F$27)),'Feuille de Donnée'!$F$32,IF(AE22<$I22*(1-'Feuille de Donnée'!$E$27),'Feuille de Donnée'!$F$33,'Feuille de Donnée'!$F$31))))) | AO22: =IF(ISBLANK(AL22),"",ROUND(AM22*AN22,2)) | AP22: =IF($H22=0,"",(AM22/$H22-1)) | AQ22: =IF($I22=0,"",(AN22/$I22-1)) | AR22: =IF(AND(ISBLANK(AT22),AS22=""),"",1+MAX(AR$18:AR21)) | AS22: =IF(OR(AO22="",AO22=0,$J22="",$J22=0,NOT(ISNUMBER($J22)),NOT(ISNUMBER(AO22))),IF(AND($G22<>"",AND(OR(ISNUMBER(AO22),AO22=""),AND(ISNUMBER($J22),$J22>0))),'Feuille de Donnée'!$K$13,""),IF(AO22<$J$165*'Feuille de Donnée'!$I$9,"Négligeable",(IF(AND(AM22>=$H22*(1-'Feuille de Donnée'!$E$12),AM22<=$H22*(1+'Feuille de Donnée'!$F$12)),'Feuille de Donnée'!$F$17,IF(AM22<$H22*(1-'Feuille de Donnée'!$E$12),'Feuille de Donnée'!$F$18,'Feuille de Donnée'!$F$16))&""&IF(AND(AN22>=$I22*(1-'Feuille de Donnée'!$E$27),AN22<=$I22*(1+'Feuille de Donnée'!$F$27)),'Feuille de Donnée'!$F$32,IF(AN22<$I22*(1-'Feuille de Donnée'!$E$27),'Feuille de Donnée'!$F$33,'Feuille de Donnée'!$F$31))))) | AX22: =IF(ISBLANK(AU22),"",ROUND(AV22*AW22,2)) | AY22: =IF($H22=0,"",(AV22/$H22-1)) | AZ22: =IF($I22=0,"",(AW22/$I22-1)) | BA22: =IF(AND(ISBLANK(BC22),BB22=""),"",1+MAX(BA$18:BA21)) | BB22: =IF(OR(AX22="",AX22=0,$J22="",$J22=0,NOT(ISNUMBER($J22)),NOT(ISNUMBER(AX22))),IF(AND($G22<>"",AND(OR(ISNUMBER(AX22),AX22=""),AND(ISNUMBER($J22),$J22>0))),'Feuille de Donnée'!$K$13,""),IF(AX22<$J$165*'Feuille de Donnée'!$I$9,"Négligeable",(IF(AND(AV22>=$H22*(1-'Feuille de Donnée'!$E$12),AV22<=$H22*(1+'Feuille de Donnée'!$F$12)),'Feuille de Donnée'!$F$17,IF(AV22<$H22*(1-'Feuille de Donnée'!$E$12),'Feuille de Donnée'!$F$18,'Feuille de Donnée'!$F$16))&""&IF(AND(AW22>=$I22*(1-'Feuille de Donnée'!$E$27),AW22<=$I22*(1+'Feuille de Donnée'!$F$27)),'Feuille de Donnée'!$F$32,IF(AW22<$I22*(1-'Feuille de Donnée'!$E$27),'Feuille de Donnée'!$F$33,'Feuille de Donnée'!$F$31))))) | BG22: =IF(ISBLANK(BD22),"",ROUND(BE22*BF22,2)) | BH22: =IF($H22=0,"",(BE22/$H22-1)) | BI22: =IF($I22=0,"",(BF22/$I22-1)) | BJ22: =IF(AND(ISBLANK(BL22),BK22=""),"",1+MAX(BJ$18:BJ21)) | BK22: =IF(OR(BG22="",BG22=0,$J22="",$J22=0,NOT(ISNUMBER($J22)),NOT(ISNUMBER(BG22))),IF(AND($G22<>"",AND(OR(ISNUMBER(BG22),BG22=""),AND(ISNUMBER($J22),$J22>0))),'Feuille de Donnée'!$K$13,""),IF(BG22<$J$165*'Feuille de Donnée'!$I$9,"Négligeable",(IF(AND(BE22>=$H22*(1-'Feuille de Donnée'!$E$12),BE22<=$H22*(1+'Feuille de Donnée'!$F$12)),'Feuille de Donnée'!$F$17,IF(BE22<$H22*(1-'Feuille de Donnée'!$E$12),'Feuille de Donnée'!$F$18,'Feuille de Donnée'!$F$16))&""&IF(AND(BF22>=$I22*(1-'Feuille de Donnée'!$E$27),BF22<=$I22*(1+'Feuille de Donnée'!$F$27)),'Feuille de Donnée'!$F$32,IF(BF22<$I22*(1-'Feuille de Donnée'!$E$27),'Feuille de Donnée'!$F$33,'Feuille de Donnée'!$F$31)))))
J23: =IF(ISBLANK(G23),"",ROUND(H23*I23,2)) | N23: =IF(ISBLANK(K23),"",ROUND(L23*M23,2)) | O23: =IF($H23=0,"",(L23/$H23-1)) | P23: =IF($I23=0,"",(M23/$I23-1)) | Q23: =IF(AND(ISBLANK(S23),R23=""),"",1+MAX(Q$18:Q22)) | R23: =IF(OR(N23="",N23=0,$J23="",$J23=0,NOT(ISNUMBER($J23)),NOT(ISNUMBER(N23))),IF(AND($G23<>"",AND(OR(ISNUMBER(N23),N23=""),AND(ISNUMBER($J23),$J23>0))),'Feuille de Donnée'!$K$13,""),IF(N23<$J$165*'Feuille de Donnée'!$I$9,"Négligeable",(IF(AND(L23>=$H23*(1-'Feuille de Donnée'!$E$12),L23<=$H23*(1+'Feuille de Donnée'!$F$12)),'Feuille de Donnée'!$F$17,IF(L23<$H23*(1-'Feuille de Donnée'!$E$12),'Feuille de Donnée'!$F$18,'Feuille de Donnée'!$F$16))&""&IF(AND(M23>=$I23*(1-'Feuille de Donnée'!$E$27),M23<=$I23*(1+'Feuille de Donnée'!$F$27)),'Feuille de Donnée'!$F$32,IF(M23<$I23*(1-'Feuille de Donnée'!$E$27),'Feuille de Donnée'!$F$33,'Feuille de Donnée'!$F$31))))) | W23: =IF(ISBLANK(T23),"",ROUND(U23*V23,2)) | X23: =IF($H23=0,"",(U23/$H23-1)) | Y23: =IF($I23=0,"",(V23/$I23-1)) | Z23: =IF(AND(ISBLANK(AB23),AA23=""),"",1+MAX(Z$18:Z22)) | AA23: =IF(OR(W23="",W23=0,$J23="",$J23=0,NOT(ISNUMBER($J23)),NOT(ISNUMBER(W23))),IF(AND($G23<>"",AND(OR(ISNUMBER(W23),W23=""),AND(ISNUMBER($J23),$J23>0))),'Feuille de Donnée'!$K$13,""),IF(W23<$J$165*'Feuille de Donnée'!$I$9,"Négligeable",(IF(AND(U23>=$H23*(1-'Feuille de Donnée'!$E$12),U23<=$H23*(1+'Feuille de Donnée'!$F$12)),'Feuille de Donnée'!$F$17,IF(U23<$H23*(1-'Feuille de Donnée'!$E$12),'Feuille de Donnée'!$F$18,'Feuille de Donnée'!$F$16))&""&IF(AND(V23>=$I23*(1-'Feuille de Donnée'!$E$27),V23<=$I23*(1+'Feuille de Donnée'!$F$27)),'Feuille de Donnée'!$F$32,IF(V23<$I23*(1-'Feuille de Donnée'!$E$27),'Feuille de Donnée'!$F$33,'Feuille de Donnée'!$F$31))))) | AF23: =IF(ISBLANK(AC23),"",ROUND(AD23*AE23,2)) | AG23: =IF($H23=0,"",(AD23/$H23-1)) | AH23: =IF($I23=0,"",(AE23/$I23-1)) | AI23: =IF(AND(ISBLANK(AK23),AJ23=""),"",1+MAX(AI$18:AI22)) | AJ23: =IF(OR(AF23="",AF23=0,$J23="",$J23=0,NOT(ISNUMBER($J23)),NOT(ISNUMBER(AF23))),IF(AND($G23<>"",AND(OR(ISNUMBER(AF23),AF23=""),AND(ISNUMBER($J23),$J23>0))),'Feuille de Donnée'!$K$13,""),IF(AF23<$J$165*'Feuille de Donnée'!$I$9,"Négligeable",(IF(AND(AD23>=$H23*(1-'Feuille de Donnée'!$E$12),AD23<=$H23*(1+'Feuille de Donnée'!$F$12)),'Feuille de Donnée'!$F$17,IF(AD23<$H23*(1-'Feuille de Donnée'!$E$12),'Feuille de Donnée'!$F$18,'Feuille de Donnée'!$F$16))&""&IF(AND(AE23>=$I23*(1-'Feuille de Donnée'!$E$27),AE23<=$I23*(1+'Feuille de Donnée'!$F$27)),'Feuille de Donnée'!$F$32,IF(AE23<$I23*(1-'Feuille de Donnée'!$E$27),'Feuille de Donnée'!$F$33,'Feuille de Donnée'!$F$31))))) | AO23: =IF(ISBLANK(AL23),"",ROUND(AM23*AN23,2)) | AP23: =IF($H23=0,"",(AM23/$H23-1)) | AQ23: =IF($I23=0,"",(AN23/$I23-1)) | AR23: =IF(AND(ISBLANK(AT23),AS23=""),"",1+MAX(AR$18:AR22)) | AS23: =IF(OR(AO23="",AO23=0,$J23="",$J23=0,NOT(ISNUMBER($J23)),NOT(ISNUMBER(AO23))),IF(AND($G23<>"",AND(OR(ISNUMBER(AO23),AO23=""),AND(ISNUMBER($J23),$J23>0))),'Feuille de Donnée'!$K$13,""),IF(AO23<$J$165*'Feuille de Donnée'!$I$9,"Négligeable",(IF(AND(AM23>=$H23*(1-'Feuille de Donnée'!$E$12),AM23<=$H23*(1+'Feuille de Donnée'!$F$12)),'Feuille de Donnée'!$F$17,IF(AM23<$H23*(1-'Feuille de Donnée'!$E$12),'Feuille de Donnée'!$F$18,'Feuille de Donnée'!$F$16))&""&IF(AND(AN23>=$I23*(1-'Feuille de Donnée'!$E$27),AN23<=$I23*(1+'Feuille de Donnée'!$F$27)),'Feuille de Donnée'!$F$32,IF(AN23<$I23*(1-'Feuille de Donnée'!$E$27),'Feuille de Donnée'!$F$33,'Feuille de Donnée'!$F$31))))) | AX23: =IF(ISBLANK(AU23),"",ROUND(AV23*AW23,2)) | AY23: =IF($H23=0,"",(AV23/$H23-1)) | AZ23: =IF($I23=0,"",(AW23/$I23-1)) | BA23: =IF(AND(ISBLANK(BC23),BB23=""),"",1+MAX(BA$18:BA22)) | BB23: =IF(OR(AX23="",AX23=0,$J23="",$J23=0,NOT(ISNUMBER($J23)),NOT(ISNUMBER(AX23))),IF(AND($G23<>"",AND(OR(ISNUMBER(AX23),AX23=""),AND(ISNUMBER($J23),$J23>0))),'Feuille de Donnée'!$K$13,""),IF(AX23<$J$165*'Feuille de Donnée'!$I$9,"Négligeable",(IF(AND(AV23>=$H23*(1-'Feuille de Donnée'!$E$12),AV23<=$H23*(1+'Feuille de Donnée'!$F$12)),'Feuille de Donnée'!$F$17,IF(AV23<$H23*(1-'Feuille de Donnée'!$E$12),'Feuille de Donnée'!$F$18,'Feuille de Donnée'!$F$16))&""&IF(AND(AW23>=$I23*(1-'Feuille de Donnée'!$E$27),AW23<=$I23*(1+'Feuille de Donnée'!$F$27)),'Feuille de Donnée'!$F$32,IF(AW23<$I23*(1-'Feuille de Donnée'!$E$27),'Feuille de Donnée'!$F$33,'Feuille de Donnée'!$F$31))))) | BG23: =IF(ISBLANK(BD23),"",ROUND(BE23*BF23,2)) | BH23: =IF($H23=0,"",(BE23/$H23-1)) | BI23: =IF($I23=0,"",(BF23/$I23-1)) | BJ23: =IF(AND(ISBLANK(BL23),BK23=""),"",1+MAX(BJ$18:BJ22)) | BK23: =IF(OR(BG23="",BG23=0,$J23="",$J23=0,NOT(ISNUMBER($J23)),NOT(ISNUMBER(BG23))),IF(AND($G23<>"",AND(OR(ISNUMBER(BG23),BG23=""),AND(ISNUMBER($J23),$J23>0))),'Feuille de Donnée'!$K$13,""),IF(BG23<$J$165*'Feuille de Donnée'!$I$9,"Négligeable",(IF(AND(BE23>=$H23*(1-'Feuille de Donnée'!$E$12),BE23<=$H23*(1+'Feuille de Donnée'!$F$12)),'Feuille de Donnée'!$F$17,IF(BE23<$H23*(1-'Feuille de Donnée'!$E$12),'Feuille de Donnée'!$F$18,'Feuille de Donnée'!$F$16))&""&IF(AND(BF23>=$I23*(1-'Feuille de Donnée'!$E$27),BF23<=$I23*(1+'Feuille de Donnée'!$F$27)),'Feuille de Donnée'!$F$32,IF(BF23<$I23*(1-'Feuille de Donnée'!$E$27),'Feuille de Donnée'!$F$33,'Feuille de Donnée'!$F$31)))))
J24: =IF(ISBLANK(G24),"",ROUND(H24*I24,2)) | N24: =IF(ISBLANK(K24),"",ROUND(L24*M24,2)) | O24: =IF($H24=0,"",(L24/$H24-1)) | P24: =IF($I24=0,"",(M24/$I24-1)) | Q24: =IF(AND(ISBLANK(S24),R24=""),"",1+MAX(Q$18:Q23)) | R24: =IF(OR(N24="",N24=0,$J24="",$J24=0,NOT(ISNUMBER($J24)),NOT(ISNUMBER(N24))),IF(AND($G24<>"",AND(OR(ISNUMBER(N24),N24=""),AND(ISNUMBER($J24),$J24>0))),'Feuille de Donnée'!$K$13,""),IF(N24<$J$165*'Feuille de Donnée'!$I$9,"Négligeable",(IF(AND(L24>=$H24*(1-'Feuille de Donnée'!$E$12),L24<=$H24*(1+'Feuille de Donnée'!$F$12)),'Feuille de Donnée'!$F$17,IF(L24<$H24*(1-'Feuille de Donnée'!$E$12),'Feuille de Donnée'!$F$18,'Feuille de Donnée'!$F$16))&""&IF(AND(M24>=$I24*(1-'Feuille de Donnée'!$E$27),M24<=$I24*(1+'Feuille de Donnée'!$F$27)),'Feuille de Donnée'!$F$32,IF(M24<$I24*(1-'Feuille de Donnée'!$E$27),'Feuille de Donnée'!$F$33,'Feuille de Donnée'!$F$31))))) | W24: =IF(ISBLANK(T24),"",ROUND(U24*V24,2)) | X24: =IF($H24=0,"",(U24/$H24-1)) | Y24: =IF($I24=0,"",(V24/$I24-1)) | Z24: =IF(AND(ISBLANK(AB24),AA24=""),"",1+MAX(Z$18:Z23)) | AA24: =IF(OR(W24="",W24=0,$J24="",$J24=0,NOT(ISNUMBER($J24)),NOT(ISNUMBER(W24))),IF(AND($G24<>"",AND(OR(ISNUMBER(W24),W24=""),AND(ISNUMBER($J24),$J24>0))),'Feuille de Donnée'!$K$13,""),IF(W24<$J$165*'Feuille de Donnée'!$I$9,"Négligeable",(IF(AND(U24>=$H24*(1-'Feuille de Donnée'!$E$12),U24<=$H24*(1+'Feuille de Donnée'!$F$12)),'Feuille de Donnée'!$F$17,IF(U24<$H24*(1-'Feuille de Donnée'!$E$12),'Feuille de Donnée'!$F$18,'Feuille de Donnée'!$F$16))&""&IF(AND(V24>=$I24*(1-'Feuille de Donnée'!$E$27),V24<=$I24*(1+'Feuille de Donnée'!$F$27)),'Feuille de Donnée'!$F$32,IF(V24<$I24*(1-'Feuille de Donnée'!$E$27),'Feuille de Donnée'!$F$33,'Feuille de Donnée'!$F$31))))) | AF24: =IF(ISBLANK(AC24),"",ROUND(AD24*AE24,2)) | AG24: =IF($H24=0,"",(AD24/$H24-1)) | AH24: =IF($I24=0,"",(AE24/$I24-1)) | AI24: =IF(AND(ISBLANK(AK24),AJ24=""),"",1+MAX(AI$18:AI23)) | AJ24: =IF(OR(AF24="",AF24=0,$J24="",$J24=0,NOT(ISNUMBER($J24)),NOT(ISNUMBER(AF24))),IF(AND($G24<>"",AND(OR(ISNUMBER(AF24),AF24=""),AND(ISNUMBER($J24),$J24>0))),'Feuille de Donnée'!$K$13,""),IF(AF24<$J$165*'Feuille de Donnée'!$I$9,"Négligeable",(IF(AND(AD24>=$H24*(1-'Feuille de Donnée'!$E$12),AD24<=$H24*(1+'Feuille de Donnée'!$F$12)),'Feuille de Donnée'!$F$17,IF(AD24<$H24*(1-'Feuille de Donnée'!$E$12),'Feuille de Donnée'!$F$18,'Feuille de Donnée'!$F$16))&""&IF(AND(AE24>=$I24*(1-'Feuille de Donnée'!$E$27),AE24<=$I24*(1+'Feuille de Donnée'!$F$27)),'Feuille de Donnée'!$F$32,IF(AE24<$I24*(1-'Feuille de Donnée'!$E$27),'Feuille de Donnée'!$F$33,'Feuille de Donnée'!$F$31))))) | AO24: =IF(ISBLANK(AL24),"",ROUND(AM24*AN24,2)) | AP24: =IF($H24=0,"",(AM24/$H24-1)) | AQ24: =IF($I24=0,"",(AN24/$I24-1)) | AR24: =IF(AND(ISBLANK(AT24),AS24=""),"",1+MAX(AR$18:AR23)) | AS24: =IF(OR(AO24="",AO24=0,$J24="",$J24=0,NOT(ISNUMBER($J24)),NOT(ISNUMBER(AO24))),IF(AND($G24<>"",AND(OR(ISNUMBER(AO24),AO24=""),AND(ISNUMBER($J24),$J24>0))),'Feuille de Donnée'!$K$13,""),IF(AO24<$J$165*'Feuille de Donnée'!$I$9,"Négligeable",(IF(AND(AM24>=$H24*(1-'Feuille de Donnée'!$E$12),AM24<=$H24*(1+'Feuille de Donnée'!$F$12)),'Feuille de Donnée'!$F$17,IF(AM24<$H24*(1-'Feuille de Donnée'!$E$12),'Feuille de Donnée'!$F$18,'Feuille de Donnée'!$F$16))&""&IF(AND(AN24>=$I24*(1-'Feuille de Donnée'!$E$27),AN24<=$I24*(1+'Feuille de Donnée'!$F$27)),'Feuille de Donnée'!$F$32,IF(AN24<$I24*(1-'Feuille de Donnée'!$E$27),'Feuille de Donnée'!$F$33,'Feuille de Donnée'!$F$31))))) | AX24: =IF(ISBLANK(AU24),"",ROUND(AV24*AW24,2)) | AY24: =IF($H24=0,"",(AV24/$H24-1)) | AZ24: =IF($I24=0,"",(AW24/$I24-1)) | BA24: =IF(AND(ISBLANK(BC24),BB24=""),"",1+MAX(BA$18:BA23)) | BB24: =IF(OR(AX24="",AX24=0,$J24="",$J24=0,NOT(ISNUMBER($J24)),NOT(ISNUMBER(AX24))),IF(AND($G24<>"",AND(OR(ISNUMBER(AX24),AX24=""),AND(ISNUMBER($J24),$J24>0))),'Feuille de Donnée'!$K$13,""),IF(AX24<$J$165*'Feuille de Donnée'!$I$9,"Négligeable",(IF(AND(AV24>=$H24*(1-'Feuille de Donnée'!$E$12),AV24<=$H24*(1+'Feuille de Donnée'!$F$12)),'Feuille de Donnée'!$F$17,IF(AV24<$H24*(1-'Feuille de Donnée'!$E$12),'Feuille de Donnée'!$F$18,'Feuille de Donnée'!$F$16))&""&IF(AND(AW24>=$I24*(1-'Feuille de Donnée'!$E$27),AW24<=$I24*(1+'Feuille de Donnée'!$F$27)),'Feuille de Donnée'!$F$32,IF(AW24<$I24*(1-'Feuille de Donnée'!$E$27),'Feuille de Donnée'!$F$33,'Feuille de Donnée'!$F$31))))) | BG24: =IF(ISBLANK(BD24),"",ROUND(BE24*BF24,2)) | BH24: =IF($H24=0,"",(BE24/$H24-1)) | BI24: =IF($I24=0,"",(BF24/$I24-1)) | BJ24: =IF(AND(ISBLANK(BL24),BK24=""),"",1+MAX(BJ$18:BJ23)) | BK24: =IF(OR(BG24="",BG24=0,$J24="",$J24=0,NOT(ISNUMBER($J24)),NOT(ISNUMBER(BG24))),IF(AND($G24<>"",AND(OR(ISNUMBER(BG24),BG24=""),AND(ISNUMBER($J24),$J24>0))),'Feuille de Donnée'!$K$13,""),IF(BG24<$J$165*'Feuille de Donnée'!$I$9,"Négligeable",(IF(AND(BE24>=$H24*(1-'Feuille de Donnée'!$E$12),BE24<=$H24*(1+'Feuille de Donnée'!$F$12)),'Feuille de Donnée'!$F$17,IF(BE24<$H24*(1-'Feuille de Donnée'!$E$12),'Feuille de Donnée'!$F$18,'Feuille de Donnée'!$F$16))&""&IF(AND(BF24>=$I24*(1-'Feuille de Donnée'!$E$27),BF24<=$I24*(1+'Feuille de Donnée'!$F$27)),'Feuille de Donnée'!$F$32,IF(BF24<$I24*(1-'Feuille de Donnée'!$E$27),'Feuille de Donnée'!$F$33,'Feuille de Donnée'!$F$31)))))
J25: =IF(ISBLANK(G25),"",ROUND(H25*I25,2)) | N25: =IF(ISBLANK(K25),"",ROUND(L25*M25,2)) | O25: =IF($H25=0,"",(L25/$H25-1)) | P25: =IF($I25=0,"",(M25/$I25-1)) | Q25: =IF(AND(ISBLANK(S25),R25=""),"",1+MAX(Q$18:Q24)) | R25: =IF(OR(N25="",N25=0,$J25="",$J25=0,NOT(ISNUMBER($J25)),NOT(ISNUMBER(N25))),IF(AND($G25<>"",AND(OR(ISNUMBER(N25),N25=""),AND(ISNUMBER($J25),$J25>0))),'Feuille de Donnée'!$K$13,""),IF(N25<$J$165*'Feuille de Donnée'!$I$9,"Négligeable",(IF(AND(L25>=$H25*(1-'Feuille de Donnée'!$E$12),L25<=$H25*(1+'Feuille de Donnée'!$F$12)),'Feuille de Donnée'!$F$17,IF(L25<$H25*(1-'Feuille de Donnée'!$E$12),'Feuille de Donnée'!$F$18,'Feuille de Donnée'!$F$16))&""&IF(AND(M25>=$I25*(1-'Feuille de Donnée'!$E$27),M25<=$I25*(1+'Feuille de Donnée'!$F$27)),'Feuille de Donnée'!$F$32,IF(M25<$I25*(1-'Feuille de Donnée'!$E$27),'Feuille de Donnée'!$F$33,'Feuille de Donnée'!$F$31))))) | W25: =IF(ISBLANK(T25),"",ROUND(U25*V25,2)) | X25: =IF($H25=0,"",(U25/$H25-1)) | Y25: =IF($I25=0,"",(V25/$I25-1)) | Z25: =IF(AND(ISBLANK(AB25),AA25=""),"",1+MAX(Z$18:Z24)) | AA25: =IF(OR(W25="",W25=0,$J25="",$J25=0,NOT(ISNUMBER($J25)),NOT(ISNUMBER(W25))),IF(AND($G25<>"",AND(OR(ISNUMBER(W25),W25=""),AND(ISNUMBER($J25),$J25>0))),'Feuille de Donnée'!$K$13,""),IF(W25<$J$165*'Feuille de Donnée'!$I$9,"Négligeable",(IF(AND(U25>=$H25*(1-'Feuille de Donnée'!$E$12),U25<=$H25*(1+'Feuille de Donnée'!$F$12)),'Feuille de Donnée'!$F$17,IF(U25<$H25*(1-'Feuille de Donnée'!$E$12),'Feuille de Donnée'!$F$18,'Feuille de Donnée'!$F$16))&""&IF(AND(V25>=$I25*(1-'Feuille de Donnée'!$E$27),V25<=$I25*(1+'Feuille de Donnée'!$F$27)),'Feuille de Donnée'!$F$32,IF(V25<$I25*(1-'Feuille de Donnée'!$E$27),'Feuille de Donnée'!$F$33,'Feuille de Donnée'!$F$31))))) | AF25: =IF(ISBLANK(AC25),"",ROUND(AD25*AE25,2)) | AG25: =IF($H25=0,"",(AD25/$H25-1)) | AH25: =IF($I25=0,"",(AE25/$I25-1)) | AI25: =IF(AND(ISBLANK(AK25),AJ25=""),"",1+MAX(AI$18:AI24)) | AJ25: =IF(OR(AF25="",AF25=0,$J25="",$J25=0,NOT(ISNUMBER($J25)),NOT(ISNUMBER(AF25))),IF(AND($G25<>"",AND(OR(ISNUMBER(AF25),AF25=""),AND(ISNUMBER($J25),$J25>0))),'Feuille de Donnée'!$K$13,""),IF(AF25<$J$165*'Feuille de Donnée'!$I$9,"Négligeable",(IF(AND(AD25>=$H25*(1-'Feuille de Donnée'!$E$12),AD25<=$H25*(1+'Feuille de Donnée'!$F$12)),'Feuille de Donnée'!$F$17,IF(AD25<$H25*(1-'Feuille de Donnée'!$E$12),'Feuille de Donnée'!$F$18,'Feuille de Donnée'!$F$16))&""&IF(AND(AE25>=$I25*(1-'Feuille de Donnée'!$E$27),AE25<=$I25*(1+'Feuille de Donnée'!$F$27)),'Feuille de Donnée'!$F$32,IF(AE25<$I25*(1-'Feuille de Donnée'!$E$27),'Feuille de Donnée'!$F$33,'Feuille de Donnée'!$F$31))))) | AO25: =IF(ISBLANK(AL25),"",ROUND(AM25*AN25,2)) | AP25: =IF($H25=0,"",(AM25/$H25-1)) | AQ25: =IF($I25=0,"",(AN25/$I25-1)) | AR25: =IF(AND(ISBLANK(AT25),AS25=""),"",1+MAX(AR$18:AR24)) | AS25: =IF(OR(AO25="",AO25=0,$J25="",$J25=0,NOT(ISNUMBER($J25)),NOT(ISNUMBER(AO25))),IF(AND($G25<>"",AND(OR(ISNUMBER(AO25),AO25=""),AND(ISNUMBER($J25),$J25>0))),'Feuille de Donnée'!$K$13,""),IF(AO25<$J$165*'Feuille de Donnée'!$I$9,"Négligeable",(IF(AND(AM25>=$H25*(1-'Feuille de Donnée'!$E$12),AM25<=$H25*(1+'Feuille de Donnée'!$F$12)),'Feuille de Donnée'!$F$17,IF(AM25<$H25*(1-'Feuille de Donnée'!$E$12),'Feuille de Donnée'!$F$18,'Feuille de Donnée'!$F$16))&""&IF(AND(AN25>=$I25*(1-'Feuille de Donnée'!$E$27),AN25<=$I25*(1+'Feuille de Donnée'!$F$27)),'Feuille de Donnée'!$F$32,IF(AN25<$I25*(1-'Feuille de Donnée'!$E$27),'Feuille de Donnée'!$F$33,'Feuille de Donnée'!$F$31))))) | AX25: =IF(ISBLANK(AU25),"",ROUND(AV25*AW25,2)) | AY25: =IF($H25=0,"",(AV25/$H25-1)) | AZ25: =IF($I25=0,"",(AW25/$I25-1)) | BA25: =IF(AND(ISBLANK(BC25),BB25=""),"",1+MAX(BA$18:BA24)) | BB25: =IF(OR(AX25="",AX25=0,$J25="",$J25=0,NOT(ISNUMBER($J25)),NOT(ISNUMBER(AX25))),IF(AND($G25<>"",AND(OR(ISNUMBER(AX25),AX25=""),AND(ISNUMBER($J25),$J25>0))),'Feuille de Donnée'!$K$13,""),IF(AX25<$J$165*'Feuille de Donnée'!$I$9,"Négligeable",(IF(AND(AV25>=$H25*(1-'Feuille de Donnée'!$E$12),AV25<=$H25*(1+'Feuille de Donnée'!$F$12)),'Feuille de Donnée'!$F$17,IF(AV25<$H25*(1-'Feuille de Donnée'!$E$12),'Feuille de Donnée'!$F$18,'Feuille de Donnée'!$F$16))&""&IF(AND(AW25>=$I25*(1-'Feuille de Donnée'!$E$27),AW25<=$I25*(1+'Feuille de Donnée'!$F$27)),'Feuille de Donnée'!$F$32,IF(AW25<$I25*(1-'Feuille de Donnée'!$E$27),'Feuille de Donnée'!$F$33,'Feuille de Donnée'!$F$31))))) | BG25: =IF(ISBLANK(BD25),"",ROUND(BE25*BF25,2)) | BH25: =IF($H25=0,"",(BE25/$H25-1)) | BI25: =IF($I25=0,"",(BF25/$I25-1)) | BJ25: =IF(AND(ISBLANK(BL25),BK25=""),"",1+MAX(BJ$18:BJ24)) | BK25: =IF(OR(BG25="",BG25=0,$J25="",$J25=0,NOT(ISNUMBER($J25)),NOT(ISNUMBER(BG25))),IF(AND($G25<>"",AND(OR(ISNUMBER(BG25),BG25=""),AND(ISNUMBER($J25),$J25>0))),'Feuille de Donnée'!$K$13,""),IF(BG25<$J$165*'Feuille de Donnée'!$I$9,"Négligeable",(IF(AND(BE25>=$H25*(1-'Feuille de Donnée'!$E$12),BE25<=$H25*(1+'Feuille de Donnée'!$F$12)),'Feuille de Donnée'!$F$17,IF(BE25<$H25*(1-'Feuille de Donnée'!$E$12),'Feuille de Donnée'!$F$18,'Feuille de Donnée'!$F$16))&""&IF(AND(BF25>=$I25*(1-'Feuille de Donnée'!$E$27),BF25<=$I25*(1+'Feuille de Donnée'!$F$27)),'Feuille de Donnée'!$F$32,IF(BF25<$I25*(1-'Feuille de Donnée'!$E$27),'Feuille de Donnée'!$F$33,'Feuille de Donnée'!$F$31)))))
J26: =IF(ISBLANK(G26),"",ROUND(H26*I26,2)) | N26: =IF(ISBLANK(K26),"",ROUND(L26*M26,2)) | O26: =IF($H26=0,"",(L26/$H26-1)) | P26: =IF($I26=0,"",(M26/$I26-1)) | Q26: =IF(AND(ISBLANK(S26),R26=""),"",1+MAX(Q$18:Q25)) | R26: =IF(OR(N26="",N26=0,$J26="",$J26=0,NOT(ISNUMBER($J26)),NOT(ISNUMBER(N26))),IF(AND($G26<>"",AND(OR(ISNUMBER(N26),N26=""),AND(ISNUMBER($J26),$J26>0))),'Feuille de Donnée'!$K$13,""),IF(N26<$J$165*'Feuille de Donnée'!$I$9,"Négligeable",(IF(AND(L26>=$H26*(1-'Feuille de Donnée'!$E$12),L26<=$H26*(1+'Feuille de Donnée'!$F$12)),'Feuille de Donnée'!$F$17,IF(L26<$H26*(1-'Feuille de Donnée'!$E$12),'Feuille de Donnée'!$F$18,'Feuille de Donnée'!$F$16))&""&IF(AND(M26>=$I26*(1-'Feuille de Donnée'!$E$27),M26<=$I26*(1+'Feuille de Donnée'!$F$27)),'Feuille de Donnée'!$F$32,IF(M26<$I26*(1-'Feuille de Donnée'!$E$27),'Feuille de Donnée'!$F$33,'Feuille de Donnée'!$F$31))))) | W26: =IF(ISBLANK(T26),"",ROUND(U26*V26,2)) | X26: =IF($H26=0,"",(U26/$H26-1)) | Y26: =IF($I26=0,"",(V26/$I26-1)) | Z26: =IF(AND(ISBLANK(AB26),AA26=""),"",1+MAX(Z$18:Z25)) | AA26: =IF(OR(W26="",W26=0,$J26="",$J26=0,NOT(ISNUMBER($J26)),NOT(ISNUMBER(W26))),IF(AND($G26<>"",AND(OR(ISNUMBER(W26),W26=""),AND(ISNUMBER($J26),$J26>0))),'Feuille de Donnée'!$K$13,""),IF(W26<$J$165*'Feuille de Donnée'!$I$9,"Négligeable",(IF(AND(U26>=$H26*(1-'Feuille de Donnée'!$E$12),U26<=$H26*(1+'Feuille de Donnée'!$F$12)),'Feuille de Donnée'!$F$17,IF(U26<$H26*(1-'Feuille de Donnée'!$E$12),'Feuille de Donnée'!$F$18,'Feuille de Donnée'!$F$16))&""&IF(AND(V26>=$I26*(1-'Feuille de Donnée'!$E$27),V26<=$I26*(1+'Feuille de Donnée'!$F$27)),'Feuille de Donnée'!$F$32,IF(V26<$I26*(1-'Feuille de Donnée'!$E$27),'Feuille de Donnée'!$F$33,'Feuille de Donnée'!$F$31))))) | AF26: =IF(ISBLANK(AC26),"",ROUND(AD26*AE26,2)) | AG26: =IF($H26=0,"",(AD26/$H26-1)) | AH26: =IF($I26=0,"",(AE26/$I26-1)) | AI26: =IF(AND(ISBLANK(AK26),AJ26=""),"",1+MAX(AI$18:AI25)) | AJ26: =IF(OR(AF26="",AF26=0,$J26="",$J26=0,NOT(ISNUMBER($J26)),NOT(ISNUMBER(AF26))),IF(AND($G26<>"",AND(OR(ISNUMBER(AF26),AF26=""),AND(ISNUMBER($J26),$J26>0))),'Feuille de Donnée'!$K$13,""),IF(AF26<$J$165*'Feuille de Donnée'!$I$9,"Négligeable",(IF(AND(AD26>=$H26*(1-'Feuille de Donnée'!$E$12),AD26<=$H26*(1+'Feuille de Donnée'!$F$12)),'Feuille de Donnée'!$F$17,IF(AD26<$H26*(1-'Feuille de Donnée'!$E$12),'Feuille de Donnée'!$F$18,'Feuille de Donnée'!$F$16))&""&IF(AND(AE26>=$I26*(1-'Feuille de Donnée'!$E$27),AE26<=$I26*(1+'Feuille de Donnée'!$F$27)),'Feuille de Donnée'!$F$32,IF(AE26<$I26*(1-'Feuille de Donnée'!$E$27),'Feuille de Donnée'!$F$33,'Feuille de Donnée'!$F$31))))) | AO26: =IF(ISBLANK(AL26),"",ROUND(AM26*AN26,2)) | AP26: =IF($H26=0,"",(AM26/$H26-1)) | AQ26: =IF($I26=0,"",(AN26/$I26-1)) | AR26: =IF(AND(ISBLANK(AT26),AS26=""),"",1+MAX(AR$18:AR25)) | AS26: =IF(OR(AO26="",AO26=0,$J26="",$J26=0,NOT(ISNUMBER($J26)),NOT(ISNUMBER(AO26))),IF(AND($G26<>"",AND(OR(ISNUMBER(AO26),AO26=""),AND(ISNUMBER($J26),$J26>0))),'Feuille de Donnée'!$K$13,""),IF(AO26<$J$165*'Feuille de Donnée'!$I$9,"Négligeable",(IF(AND(AM26>=$H26*(1-'Feuille de Donnée'!$E$12),AM26<=$H26*(1+'Feuille de Donnée'!$F$12)),'Feuille de Donnée'!$F$17,IF(AM26<$H26*(1-'Feuille de Donnée'!$E$12),'Feuille de Donnée'!$F$18,'Feuille de Donnée'!$F$16))&""&IF(AND(AN26>=$I26*(1-'Feuille de Donnée'!$E$27),AN26<=$I26*(1+'Feuille de Donnée'!$F$27)),'Feuille de Donnée'!$F$32,IF(AN26<$I26*(1-'Feuille de Donnée'!$E$27),'Feuille de Donnée'!$F$33,'Feuille de Donnée'!$F$31))))) | AX26: =IF(ISBLANK(AU26),"",ROUND(AV26*AW26,2)) | AY26: =IF($H26=0,"",(AV26/$H26-1)) | AZ26: =IF($I26=0,"",(AW26/$I26-1)) | BA26: =IF(AND(ISBLANK(BC26),BB26=""),"",1+MAX(BA$18:BA25)) | BB26: =IF(OR(AX26="",AX26=0,$J26="",$J26=0,NOT(ISNUMBER($J26)),NOT(ISNUMBER(AX26))),IF(AND($G26<>"",AND(OR(ISNUMBER(AX26),AX26=""),AND(ISNUMBER($J26),$J26>0))),'Feuille de Donnée'!$K$13,""),IF(AX26<$J$165*'Feuille de Donnée'!$I$9,"Négligeable",(IF(AND(AV26>=$H26*(1-'Feuille de Donnée'!$E$12),AV26<=$H26*(1+'Feuille de Donnée'!$F$12)),'Feuille de Donnée'!$F$17,IF(AV26<$H26*(1-'Feuille de Donnée'!$E$12),'Feuille de Donnée'!$F$18,'Feuille de Donnée'!$F$16))&""&IF(AND(AW26>=$I26*(1-'Feuille de Donnée'!$E$27),AW26<=$I26*(1+'Feuille de Donnée'!$F$27)),'Feuille de Donnée'!$F$32,IF(AW26<$I26*(1-'Feuille de Donnée'!$E$27),'Feuille de Donnée'!$F$33,'Feuille de Donnée'!$F$31))))) | BG26: =IF(ISBLANK(BD26),"",ROUND(BE26*BF26,2)) | BH26: =IF($H26=0,"",(BE26/$H26-1)) | BI26: =IF($I26=0,"",(BF26/$I26-1)) | BJ26: =IF(AND(ISBLANK(BL26),BK26=""),"",1+MAX(BJ$18:BJ25)) | BK26: =IF(OR(BG26="",BG26=0,$J26="",$J26=0,NOT(ISNUMBER($J26)),NOT(ISNUMBER(BG26))),IF(AND($G26<>"",AND(OR(ISNUMBER(BG26),BG26=""),AND(ISNUMBER($J26),$J26>0))),'Feuille de Donnée'!$K$13,""),IF(BG26<$J$165*'Feuille de Donnée'!$I$9,"Négligeable",(IF(AND(BE26>=$H26*(1-'Feuille de Donnée'!$E$12),BE26<=$H26*(1+'Feuille de Donnée'!$F$12)),'Feuille de Donnée'!$F$17,IF(BE26<$H26*(1-'Feuille de Donnée'!$E$12),'Feuille de Donnée'!$F$18,'Feuille de Donnée'!$F$16))&""&IF(AND(BF26>=$I26*(1-'Feuille de Donnée'!$E$27),BF26<=$I26*(1+'Feuille de Donnée'!$F$27)),'Feuille de Donnée'!$F$32,IF(BF26<$I26*(1-'Feuille de Donnée'!$E$27),'Feuille de Donnée'!$F$33,'Feuille de Donnée'!$F$31)))))
J27: =IF(ISBLANK(G27),"",ROUND(H27*I27,2)) | N27: =IF(ISBLANK(K27),"",ROUND(L27*M27,2)) | O27: =IF($H27=0,"",(L27/$H27-1)) | P27: =IF($I27=0,"",(M27/$I27-1)) | Q27: =IF(AND(ISBLANK(S27),R27=""),"",1+MAX(Q$18:Q26)) | R27: =IF(OR(N27="",N27=0,$J27="",$J27=0,NOT(ISNUMBER($J27)),NOT(ISNUMBER(N27))),IF(AND($G27<>"",AND(OR(ISNUMBER(N27),N27=""),AND(ISNUMBER($J27),$J27>0))),'Feuille de Donnée'!$K$13,""),IF(N27<$J$165*'Feuille de Donnée'!$I$9,"Négligeable",(IF(AND(L27>=$H27*(1-'Feuille de Donnée'!$E$12),L27<=$H27*(1+'Feuille de Donnée'!$F$12)),'Feuille de Donnée'!$F$17,IF(L27<$H27*(1-'Feuille de Donnée'!$E$12),'Feuille de Donnée'!$F$18,'Feuille de Donnée'!$F$16))&""&IF(AND(M27>=$I27*(1-'Feuille de Donnée'!$E$27),M27<=$I27*(1+'Feuille de Donnée'!$F$27)),'Feuille de Donnée'!$F$32,IF(M27<$I27*(1-'Feuille de Donnée'!$E$27),'Feuille de Donnée'!$F$33,'Feuille de Donnée'!$F$31))))) | W27: =IF(ISBLANK(T27),"",ROUND(U27*V27,2)) | X27: =IF($H27=0,"",(U27/$H27-1)) | Y27: =IF($I27=0,"",(V27/$I27-1)) | Z27: =IF(AND(ISBLANK(AB27),AA27=""),"",1+MAX(Z$18:Z26)) | AA27: =IF(OR(W27="",W27=0,$J27="",$J27=0,NOT(ISNUMBER($J27)),NOT(ISNUMBER(W27))),IF(AND($G27<>"",AND(OR(ISNUMBER(W27),W27=""),AND(ISNUMBER($J27),$J27>0))),'Feuille de Donnée'!$K$13,""),IF(W27<$J$165*'Feuille de Donnée'!$I$9,"Négligeable",(IF(AND(U27>=$H27*(1-'Feuille de Donnée'!$E$12),U27<=$H27*(1+'Feuille de Donnée'!$F$12)),'Feuille de Donnée'!$F$17,IF(U27<$H27*(1-'Feuille de Donnée'!$E$12),'Feuille de Donnée'!$F$18,'Feuille de Donnée'!$F$16))&""&IF(AND(V27>=$I27*(1-'Feuille de Donnée'!$E$27),V27<=$I27*(1+'Feuille de Donnée'!$F$27)),'Feuille de Donnée'!$F$32,IF(V27<$I27*(1-'Feuille de Donnée'!$E$27),'Feuille de Donnée'!$F$33,'Feuille de Donnée'!$F$31))))) | AF27: =IF(ISBLANK(AC27),"",ROUND(AD27*AE27,2)) | AG27: =IF($H27=0,"",(AD27/$H27-1)) | AH27: =IF($I27=0,"",(AE27/$I27-1)) | AI27: =IF(AND(ISBLANK(AK27),AJ27=""),"",1+MAX(AI$18:AI26)) | AJ27: =IF(OR(AF27="",AF27=0,$J27="",$J27=0,NOT(ISNUMBER($J27)),NOT(ISNUMBER(AF27))),IF(AND($G27<>"",AND(OR(ISNUMBER(AF27),AF27=""),AND(ISNUMBER($J27),$J27>0))),'Feuille de Donnée'!$K$13,""),IF(AF27<$J$165*'Feuille de Donnée'!$I$9,"Négligeable",(IF(AND(AD27>=$H27*(1-'Feuille de Donnée'!$E$12),AD27<=$H27*(1+'Feuille de Donnée'!$F$12)),'Feuille de Donnée'!$F$17,IF(AD27<$H27*(1-'Feuille de Donnée'!$E$12),'Feuille de Donnée'!$F$18,'Feuille de Donnée'!$F$16))&""&IF(AND(AE27>=$I27*(1-'Feuille de Donnée'!$E$27),AE27<=$I27*(1+'Feuille de Donnée'!$F$27)),'Feuille de Donnée'!$F$32,IF(AE27<$I27*(1-'Feuille de Donnée'!$E$27),'Feuille de Donnée'!$F$33,'Feuille de Donnée'!$F$31))))) | AO27: =IF(ISBLANK(AL27),"",ROUND(AM27*AN27,2)) | AP27: =IF($H27=0,"",(AM27/$H27-1)) | AQ27: =IF($I27=0,"",(AN27/$I27-1)) | AR27: =IF(AND(ISBLANK(AT27),AS27=""),"",1+MAX(AR$18:AR26)) | AS27: =IF(OR(AO27="",AO27=0,$J27="",$J27=0,NOT(ISNUMBER($J27)),NOT(ISNUMBER(AO27))),IF(AND($G27<>"",AND(OR(ISNUMBER(AO27),AO27=""),AND(ISNUMBER($J27),$J27>0))),'Feuille de Donnée'!$K$13,""),IF(AO27<$J$165*'Feuille de Donnée'!$I$9,"Négligeable",(IF(AND(AM27>=$H27*(1-'Feuille de Donnée'!$E$12),AM27<=$H27*(1+'Feuille de Donnée'!$F$12)),'Feuille de Donnée'!$F$17,IF(AM27<$H27*(1-'Feuille de Donnée'!$E$12),'Feuille de Donnée'!$F$18,'Feuille de Donnée'!$F$16))&""&IF(AND(AN27>=$I27*(1-'Feuille de Donnée'!$E$27),AN27<=$I27*(1+'Feuille de Donnée'!$F$27)),'Feuille de Donnée'!$F$32,IF(AN27<$I27*(1-'Feuille de Donnée'!$E$27),'Feuille de Donnée'!$F$33,'Feuille de Donnée'!$F$31))))) | AX27: =IF(ISBLANK(AU27),"",ROUND(AV27*AW27,2)) | AY27: =IF($H27=0,"",(AV27/$H27-1)) | AZ27: =IF($I27=0,"",(AW27/$I27-1)) | BA27: =IF(AND(ISBLANK(BC27),BB27=""),"",1+MAX(BA$18:BA26)) | BB27: =IF(OR(AX27="",AX27=0,$J27="",$J27=0,NOT(ISNUMBER($J27)),NOT(ISNUMBER(AX27))),IF(AND($G27<>"",AND(OR(ISNUMBER(AX27),AX27=""),AND(ISNUMBER($J27),$J27>0))),'Feuille de Donnée'!$K$13,""),IF(AX27<$J$165*'Feuille de Donnée'!$I$9,"Négligeable",(IF(AND(AV27>=$H27*(1-'Feuille de Donnée'!$E$12),AV27<=$H27*(1+'Feuille de Donnée'!$F$12)),'Feuille de Donnée'!$F$17,IF(AV27<$H27*(1-'Feuille de Donnée'!$E$12),'Feuille de Donnée'!$F$18,'Feuille de Donnée'!$F$16))&""&IF(AND(AW27>=$I27*(1-'Feuille de Donnée'!$E$27),AW27<=$I27*(1+'Feuille de Donnée'!$F$27)),'Feuille de Donnée'!$F$32,IF(AW27<$I27*(1-'Feuille de Donnée'!$E$27),'Feuille de Donnée'!$F$33,'Feuille de Donnée'!$F$31))))) | BG27: =IF(ISBLANK(BD27),"",ROUND(BE27*BF27,2)) | BH27: =IF($H27=0,"",(BE27/$H27-1)) | BI27: =IF($I27=0,"",(BF27/$I27-1)) | BJ27: =IF(AND(ISBLANK(BL27),BK27=""),"",1+MAX(BJ$18:BJ26)) | BK27: =IF(OR(BG27="",BG27=0,$J27="",$J27=0,NOT(ISNUMBER($J27)),NOT(ISNUMBER(BG27))),IF(AND($G27<>"",AND(OR(ISNUMBER(BG27),BG27=""),AND(ISNUMBER($J27),$J27>0))),'Feuille de Donnée'!$K$13,""),IF(BG27<$J$165*'Feuille de Donnée'!$I$9,"Négligeable",(IF(AND(BE27>=$H27*(1-'Feuille de Donnée'!$E$12),BE27<=$H27*(1+'Feuille de Donnée'!$F$12)),'Feuille de Donnée'!$F$17,IF(BE27<$H27*(1-'Feuille de Donnée'!$E$12),'Feuille de Donnée'!$F$18,'Feuille de Donnée'!$F$16))&""&IF(AND(BF27>=$I27*(1-'Feuille de Donnée'!$E$27),BF27<=$I27*(1+'Feuille de Donnée'!$F$27)),'Feuille de Donnée'!$F$32,IF(BF27<$I27*(1-'Feuille de Donnée'!$E$27),'Feuille de Donnée'!$F$33,'Feuille de Donnée'!$F$31)))))
J28: =IF(ISBLANK(G28),"",ROUND(H28*I28,2)) | N28: =IF(ISBLANK(K28),"",ROUND(L28*M28,2)) | O28: =IF($H28=0,"",(L28/$H28-1)) | P28: =IF($I28=0,"",(M28/$I28-1)) | Q28: =IF(AND(ISBLANK(S28),R28=""),"",1+MAX(Q$18:Q27)) | R28: =IF(OR(N28="",N28=0,$J28="",$J28=0,NOT(ISNUMBER($J28)),NOT(ISNUMBER(N28))),IF(AND($G28<>"",AND(OR(ISNUMBER(N28),N28=""),AND(ISNUMBER($J28),$J28>0))),'Feuille de Donnée'!$K$13,""),IF(N28<$J$165*'Feuille de Donnée'!$I$9,"Négligeable",(IF(AND(L28>=$H28*(1-'Feuille de Donnée'!$E$12),L28<=$H28*(1+'Feuille de Donnée'!$F$12)),'Feuille de Donnée'!$F$17,IF(L28<$H28*(1-'Feuille de Donnée'!$E$12),'Feuille de Donnée'!$F$18,'Feuille de Donnée'!$F$16))&""&IF(AND(M28>=$I28*(1-'Feuille de Donnée'!$E$27),M28<=$I28*(1+'Feuille de Donnée'!$F$27)),'Feuille de Donnée'!$F$32,IF(M28<$I28*(1-'Feuille de Donnée'!$E$27),'Feuille de Donnée'!$F$33,'Feuille de Donnée'!$F$31))))) | W28: =IF(ISBLANK(T28),"",ROUND(U28*V28,2)) | X28: =IF($H28=0,"",(U28/$H28-1)) | Y28: =IF($I28=0,"",(V28/$I28-1)) | Z28: =IF(AND(ISBLANK(AB28),AA28=""),"",1+MAX(Z$18:Z27)) | AA28: =IF(OR(W28="",W28=0,$J28="",$J28=0,NOT(ISNUMBER($J28)),NOT(ISNUMBER(W28))),IF(AND($G28<>"",AND(OR(ISNUMBER(W28),W28=""),AND(ISNUMBER($J28),$J28>0))),'Feuille de Donnée'!$K$13,""),IF(W28<$J$165*'Feuille de Donnée'!$I$9,"Négligeable",(IF(AND(U28>=$H28*(1-'Feuille de Donnée'!$E$12),U28<=$H28*(1+'Feuille de Donnée'!$F$12)),'Feuille de Donnée'!$F$17,IF(U28<$H28*(1-'Feuille de Donnée'!$E$12),'Feuille de Donnée'!$F$18,'Feuille de Donnée'!$F$16))&""&IF(AND(V28>=$I28*(1-'Feuille de Donnée'!$E$27),V28<=$I28*(1+'Feuille de Donnée'!$F$27)),'Feuille de Donnée'!$F$32,IF(V28<$I28*(1-'Feuille de Donnée'!$E$27),'Feuille de Donnée'!$F$33,'Feuille de Donnée'!$F$31))))) | AF28: =IF(ISBLANK(AC28),"",ROUND(AD28*AE28,2)) | AG28: =IF($H28=0,"",(AD28/$H28-1)) | AH28: =IF($I28=0,"",(AE28/$I28-1)) | AI28: =IF(AND(ISBLANK(AK28),AJ28=""),"",1+MAX(AI$18:AI27)) | AJ28: =IF(OR(AF28="",AF28=0,$J28="",$J28=0,NOT(ISNUMBER($J28)),NOT(ISNUMBER(AF28))),IF(AND($G28<>"",AND(OR(ISNUMBER(AF28),AF28=""),AND(ISNUMBER($J28),$J28>0))),'Feuille de Donnée'!$K$13,""),IF(AF28<$J$165*'Feuille de Donnée'!$I$9,"Négligeable",(IF(AND(AD28>=$H28*(1-'Feuille de Donnée'!$E$12),AD28<=$H28*(1+'Feuille de Donnée'!$F$12)),'Feuille de Donnée'!$F$17,IF(AD28<$H28*(1-'Feuille de Donnée'!$E$12),'Feuille de Donnée'!$F$18,'Feuille de Donnée'!$F$16))&""&IF(AND(AE28>=$I28*(1-'Feuille de Donnée'!$E$27),AE28<=$I28*(1+'Feuille de Donnée'!$F$27)),'Feuille de Donnée'!$F$32,IF(AE28<$I28*(1-'Feuille de Donnée'!$E$27),'Feuille de Donnée'!$F$33,'Feuille de Donnée'!$F$31))))) | AO28: =IF(ISBLANK(AL28),"",ROUND(AM28*AN28,2)) | AP28: =IF($H28=0,"",(AM28/$H28-1)) | AQ28: =IF($I28=0,"",(AN28/$I28-1)) | AR28: =IF(AND(ISBLANK(AT28),AS28=""),"",1+MAX(AR$18:AR27)) | AS28: =IF(OR(AO28="",AO28=0,$J28="",$J28=0,NOT(ISNUMBER($J28)),NOT(ISNUMBER(AO28))),IF(AND($G28<>"",AND(OR(ISNUMBER(AO28),AO28=""),AND(ISNUMBER($J28),$J28>0))),'Feuille de Donnée'!$K$13,""),IF(AO28<$J$165*'Feuille de Donnée'!$I$9,"Négligeable",(IF(AND(AM28>=$H28*(1-'Feuille de Donnée'!$E$12),AM28<=$H28*(1+'Feuille de Donnée'!$F$12)),'Feuille de Donnée'!$F$17,IF(AM28<$H28*(1-'Feuille de Donnée'!$E$12),'Feuille de Donnée'!$F$18,'Feuille de Donnée'!$F$16))&""&IF(AND(AN28>=$I28*(1-'Feuille de Donnée'!$E$27),AN28<=$I28*(1+'Feuille de Donnée'!$F$27)),'Feuille de Donnée'!$F$32,IF(AN28<$I28*(1-'Feuille de Donnée'!$E$27),'Feuille de Donnée'!$F$33,'Feuille de Donnée'!$F$31))))) | AX28: =IF(ISBLANK(AU28),"",ROUND(AV28*AW28,2)) | AY28: =IF($H28=0,"",(AV28/$H28-1)) | AZ28: =IF($I28=0,"",(AW28/$I28-1)) | BA28: =IF(AND(ISBLANK(BC28),BB28=""),"",1+MAX(BA$18:BA27)) | BB28: =IF(OR(AX28="",AX28=0,$J28="",$J28=0,NOT(ISNUMBER($J28)),NOT(ISNUMBER(AX28))),IF(AND($G28<>"",AND(OR(ISNUMBER(AX28),AX28=""),AND(ISNUMBER($J28),$J28>0))),'Feuille de Donnée'!$K$13,""),IF(AX28<$J$165*'Feuille de Donnée'!$I$9,"Négligeable",(IF(AND(AV28>=$H28*(1-'Feuille de Donnée'!$E$12),AV28<=$H28*(1+'Feuille de Donnée'!$F$12)),'Feuille de Donnée'!$F$17,IF(AV28<$H28*(1-'Feuille de Donnée'!$E$12),'Feuille de Donnée'!$F$18,'Feuille de Donnée'!$F$16))&""&IF(AND(AW28>=$I28*(1-'Feuille de Donnée'!$E$27),AW28<=$I28*(1+'Feuille de Donnée'!$F$27)),'Feuille de Donnée'!$F$32,IF(AW28<$I28*(1-'Feuille de Donnée'!$E$27),'Feuille de Donnée'!$F$33,'Feuille de Donnée'!$F$31))))) | BG28: =IF(ISBLANK(BD28),"",ROUND(BE28*BF28,2)) | BH28: =IF($H28=0,"",(BE28/$H28-1)) | BI28: =IF($I28=0,"",(BF28/$I28-1)) | BJ28: =IF(AND(ISBLANK(BL28),BK28=""),"",1+MAX(BJ$18:BJ27)) | BK28: =IF(OR(BG28="",BG28=0,$J28="",$J28=0,NOT(ISNUMBER($J28)),NOT(ISNUMBER(BG28))),IF(AND($G28<>"",AND(OR(ISNUMBER(BG28),BG28=""),AND(ISNUMBER($J28),$J28>0))),'Feuille de Donnée'!$K$13,""),IF(BG28<$J$165*'Feuille de Donnée'!$I$9,"Négligeable",(IF(AND(BE28>=$H28*(1-'Feuille de Donnée'!$E$12),BE28<=$H28*(1+'Feuille de Donnée'!$F$12)),'Feuille de Donnée'!$F$17,IF(BE28<$H28*(1-'Feuille de Donnée'!$E$12),'Feuille de Donnée'!$F$18,'Feuille de Donnée'!$F$16))&""&IF(AND(BF28>=$I28*(1-'Feuille de Donnée'!$E$27),BF28<=$I28*(1+'Feuille de Donnée'!$F$27)),'Feuille de Donnée'!$F$32,IF(BF28<$I28*(1-'Feuille de Donnée'!$E$27),'Feuille de Donnée'!$F$33,'Feuille de Donnée'!$F$31)))))
